[2022-02-07 16:37:26,853] {taskinstance.py:1032} INFO - Dependencies all met for <TaskInstance: simple_etl_dag.run_etl_task manual__2022-02-07T16:37:24.393479+00:00 [queued]>
[2022-02-07 16:37:26,864] {taskinstance.py:1032} INFO - Dependencies all met for <TaskInstance: simple_etl_dag.run_etl_task manual__2022-02-07T16:37:24.393479+00:00 [queued]>
[2022-02-07 16:37:26,864] {taskinstance.py:1238} INFO - 
--------------------------------------------------------------------------------
[2022-02-07 16:37:26,864] {taskinstance.py:1239} INFO - Starting attempt 1 of 1
[2022-02-07 16:37:26,864] {taskinstance.py:1240} INFO - 
--------------------------------------------------------------------------------
[2022-02-07 16:37:26,876] {taskinstance.py:1259} INFO - Executing <Task(PythonOperator): run_etl_task> on 2022-02-07 16:37:24.393479+00:00
[2022-02-07 16:37:26,882] {standard_task_runner.py:52} INFO - Started process 2211 to run task
[2022-02-07 16:37:26,885] {standard_task_runner.py:76} INFO - Running: ['***', 'tasks', 'run', 'simple_etl_dag', 'run_etl_task', 'manual__2022-02-07T16:37:24.393479+00:00', '--job-id', '2', '--raw', '--subdir', 'DAGS_FOLDER/simple_etl_dag.py', '--cfg-path', '/tmp/tmprv8dnu0u', '--error-file', '/tmp/tmp5_qohf3m']
[2022-02-07 16:37:26,886] {standard_task_runner.py:77} INFO - Job 2: Subtask run_etl_task
[2022-02-07 16:37:26,934] {logging_mixin.py:109} INFO - Running <TaskInstance: simple_etl_dag.run_etl_task manual__2022-02-07T16:37:24.393479+00:00 [running]> on host 3be96e2e1ca8
[2022-02-07 16:37:26,979] {taskinstance.py:1426} INFO - Exporting the following env vars:
AIRFLOW_CTX_DAG_OWNER=Airflow
AIRFLOW_CTX_DAG_ID=simple_etl_dag
AIRFLOW_CTX_TASK_ID=run_etl_task
AIRFLOW_CTX_EXECUTION_DATE=2022-02-07T16:37:24.393479+00:00
AIRFLOW_CTX_DAG_RUN_ID=manual__2022-02-07T16:37:24.393479+00:00
[2022-02-07 16:37:26,980] {logging_mixin.py:109} INFO - >>> Running 'etl' function. Logged at 2022-02-07 16:37:26.980714+00:00
[2022-02-07 16:37:26,980] {logging_mixin.py:109} INFO - >>> Running 'connect_db' function. Logged at 2022-02-07 16:37:26.980882+00:00
[2022-02-07 16:37:26,980] {logging_mixin.py:109} INFO - Connecting to DB
[2022-02-07 16:37:26,981] {taskinstance.py:1700} ERROR - Task failed with exception
Traceback (most recent call last):
  File "/home/airflow/.local/lib/python3.7/site-packages/airflow/models/taskinstance.py", line 1329, in _run_raw_task
    self._execute_task_with_callbacks(context)
  File "/home/airflow/.local/lib/python3.7/site-packages/airflow/models/taskinstance.py", line 1455, in _execute_task_with_callbacks
    result = self._execute_task(context, self.task)
  File "/home/airflow/.local/lib/python3.7/site-packages/airflow/models/taskinstance.py", line 1511, in _execute_task
    result = execute_callable(context=context)
  File "/home/airflow/.local/lib/python3.7/site-packages/airflow/operators/python.py", line 174, in execute
    return_value = self.execute_callable()
  File "/home/airflow/.local/lib/python3.7/site-packages/airflow/operators/python.py", line 185, in execute_callable
    return self.python_callable(*self.op_args, **self.op_kwargs)
  File "/opt/airflow/dags/simple_etl_dag.py", line 35, in wrapper
    to_execute = func(*args, **kwargs)
  File "/opt/airflow/dags/simple_etl_dag.py", line 102, in etl
    db_engine = connect_db()
  File "/opt/airflow/dags/simple_etl_dag.py", line 35, in wrapper
    to_execute = func(*args, **kwargs)
  File "/opt/airflow/dags/simple_etl_dag.py", line 53, in connect_db
    engine = create_engine(connection_uri, pool_pre_ping=True)
  File "/home/airflow/.local/lib/python3.7/site-packages/sqlalchemy/engine/__init__.py", line 525, in create_engine
    return strategy.create(*args, **kwargs)
  File "/home/airflow/.local/lib/python3.7/site-packages/sqlalchemy/engine/strategies.py", line 54, in create
    u = url.make_url(name_or_url)
  File "/home/airflow/.local/lib/python3.7/site-packages/sqlalchemy/engine/url.py", line 229, in make_url
    return _parse_rfc1738_args(name_or_url)
  File "/home/airflow/.local/lib/python3.7/site-packages/sqlalchemy/engine/url.py", line 288, in _parse_rfc1738_args
    return URL(name, **components)
  File "/home/airflow/.local/lib/python3.7/site-packages/sqlalchemy/engine/url.py", line 71, in __init__
    self.port = int(port)
ValueError: invalid literal for int() with base 10: '5432AIRFLOW_UID=1000'
[2022-02-07 16:37:26,995] {taskinstance.py:1277} INFO - Marking task as FAILED. dag_id=simple_etl_dag, task_id=run_etl_task, execution_date=20220207T163724, start_date=20220207T163726, end_date=20220207T163726
[2022-02-07 16:37:27,010] {standard_task_runner.py:92} ERROR - Failed to execute job 2 for task run_etl_task
Traceback (most recent call last):
  File "/home/airflow/.local/lib/python3.7/site-packages/airflow/task/task_runner/standard_task_runner.py", line 85, in _start_by_fork
    args.func(args, dag=self.dag)
  File "/home/airflow/.local/lib/python3.7/site-packages/airflow/cli/cli_parser.py", line 48, in command
    return func(*args, **kwargs)
  File "/home/airflow/.local/lib/python3.7/site-packages/airflow/utils/cli.py", line 92, in wrapper
    return f(*args, **kwargs)
  File "/home/airflow/.local/lib/python3.7/site-packages/airflow/cli/commands/task_command.py", line 298, in task_run
    _run_task_by_selected_method(args, dag, ti)
  File "/home/airflow/.local/lib/python3.7/site-packages/airflow/cli/commands/task_command.py", line 107, in _run_task_by_selected_method
    _run_raw_task(args, ti)
  File "/home/airflow/.local/lib/python3.7/site-packages/airflow/cli/commands/task_command.py", line 184, in _run_raw_task
    error_file=args.error_file,
  File "/home/airflow/.local/lib/python3.7/site-packages/airflow/utils/session.py", line 70, in wrapper
    return func(*args, session=session, **kwargs)
  File "/home/airflow/.local/lib/python3.7/site-packages/airflow/models/taskinstance.py", line 1329, in _run_raw_task
    self._execute_task_with_callbacks(context)
  File "/home/airflow/.local/lib/python3.7/site-packages/airflow/models/taskinstance.py", line 1455, in _execute_task_with_callbacks
    result = self._execute_task(context, self.task)
  File "/home/airflow/.local/lib/python3.7/site-packages/airflow/models/taskinstance.py", line 1511, in _execute_task
    result = execute_callable(context=context)
  File "/home/airflow/.local/lib/python3.7/site-packages/airflow/operators/python.py", line 174, in execute
    return_value = self.execute_callable()
  File "/home/airflow/.local/lib/python3.7/site-packages/airflow/operators/python.py", line 185, in execute_callable
    return self.python_callable(*self.op_args, **self.op_kwargs)
  File "/opt/airflow/dags/simple_etl_dag.py", line 35, in wrapper
    to_execute = func(*args, **kwargs)
  File "/opt/airflow/dags/simple_etl_dag.py", line 102, in etl
    db_engine = connect_db()
  File "/opt/airflow/dags/simple_etl_dag.py", line 35, in wrapper
    to_execute = func(*args, **kwargs)
  File "/opt/airflow/dags/simple_etl_dag.py", line 53, in connect_db
    engine = create_engine(connection_uri, pool_pre_ping=True)
  File "/home/airflow/.local/lib/python3.7/site-packages/sqlalchemy/engine/__init__.py", line 525, in create_engine
    return strategy.create(*args, **kwargs)
  File "/home/airflow/.local/lib/python3.7/site-packages/sqlalchemy/engine/strategies.py", line 54, in create
    u = url.make_url(name_or_url)
  File "/home/airflow/.local/lib/python3.7/site-packages/sqlalchemy/engine/url.py", line 229, in make_url
    return _parse_rfc1738_args(name_or_url)
  File "/home/airflow/.local/lib/python3.7/site-packages/sqlalchemy/engine/url.py", line 288, in _parse_rfc1738_args
    return URL(name, **components)
  File "/home/airflow/.local/lib/python3.7/site-packages/sqlalchemy/engine/url.py", line 71, in __init__
    self.port = int(port)
ValueError: invalid literal for int() with base 10: '5432AIRFLOW_UID=1000'
[2022-02-07 16:37:27,057] {local_task_job.py:154} INFO - Task exited with return code 1
[2022-02-07 16:37:27,097] {local_task_job.py:264} INFO - 0 downstream tasks scheduled from follow-on schedule check
